Workbook

Sheet Prospectos iMile
A1: Prioridad | B1: Razón social | C1: Ciudad de recolección | D1: Industria / giro | E1: Ingreso anual con Estafeta (MXN) | F1: Contacto 1 | G1: Celular | H1: Correo | I1: Contacto 2 | J1: Correo 2 | K1: Nota de fit iMile | L1: Errores / datos a corregir
A2: =IF(E2>=20000000,"1 - Alta",IF(E2>=5000000,"2 - Media","3 - Baja")) -> 1 - Alta | B2: CYBERPUERTA | C2: Guadalajara | D2: Electrónica - eCommerce puro | E2: 1.0357539e+08 | F2: Jan Plessow | G2: 3331916909 | H2: j.plessow@cyberpuerta.mx | I2: Cristian Miranda | J2: c.miranda@cyberpuerta.mx | K2: Líder ecommerce tech GDL, paquete pequeño, alto volumen
A3: =IF(E3>=20000000,"1 - Alta",IF(E3>=5000000,"2 - Media","3 - Baja")) -> 1 - Alta | B3: INNOVA SPORT | C3: Monterrey | D3: Moda deportiva omnicanal | E3: 1.0316996e+08 | F3: Axel Valdes | G3: 8126214808 | H3: axel.valdez@innovasport.com | K3: Retail deportivo MTY con fuerte canal online
A4: =IF(E4>=20000000,"1 - Alta",IF(E4>=5000000,"2 - Media","3 - Baja")) -> 1 - Alta | B4: TRENDIER MEXICO | C4: CDMX Sur | D4: Moda - marketplace C2C | E4: 82465731 | F4: Aloma Garcia | G4: 5544917842 | H4: aloma.garcia@gotrendier.mx | I4: Aloma Garcia | J4: aloma.garcia@gotrendier.mx | K4: Marketplace de moda 2a mano, 100% envíos individuales CDMX
A5: =IF(E5>=20000000,"1 - Alta",IF(E5>=5000000,"2 - Media","3 - Baja")) -> 1 - Alta | B5: NATURA DISTRIBUIDORA DE MEXICO | C5: CDMX (multinivel) | D5: Belleza - venta directa | E5: 68792150 | F5: Alejandro Martinez | G5: 5520462463 | H5: alejandromartinez@natura.net | K5: Multinivel: miles de paquetes pequeños diarios, CEDIS EdoMex
A6: =IF(E6>=20000000,"1 - Alta",IF(E6>=5000000,"2 - Media","3 - Baja")) -> 1 - Alta | B6: GRUPO VENTROTEC | C6: Guadalajara | D6: Electrónica B2B | E6: 49978386 | F6: JUAN CARLOS CRUZ | G6: 3331675491 | H6: logistica@ventronic.com.mx | K6: Ventronic GDL, envíos frecuentes
A7: =IF(E7>=20000000,"1 - Alta",IF(E7>=5000000,"2 - Media","3 - Baja")) -> 1 - Alta | B7: PRICE SERVICES & TRADE | C7: CDMX Sur | D7: Calzado/moda por catálogo | E7: 42351062 | F7: Jorge Pinzon | G7: 5573968728 | H7: jorge.pinzon@priceshoes.com | K7: Price Shoes: venta por catálogo, miles de envíos B2C
A8: =IF(E8>=20000000,"1 - Alta",IF(E8>=5000000,"2 - Media","3 - Baja")) -> 1 - Alta | B8: AUTOZONE DE MEXICO | C8: Monterrey | D8: Refacciones auto | E8: 41585713 | F8: GUILLERMO VALDEZ | G8: 1162541055 | H8: gvaltierra@grupoaxo.com | I8: LUIS ALBERTO MARTINEZ | J8: alberto.martinez@autozone.com | K8: Paquete ligero-mediano, red MTY; ecommerce creciendo | L8: Correo no corresponde al dominio de la empresa (grupoaxo.com)
A9: =IF(E9>=20000000,"1 - Alta",IF(E9>=5000000,"2 - Media","3 - Baja")) -> 1 - Alta | B9: ORIFLAME MEXICO | C9: CDMX (multinivel) | D9: Belleza - venta directa | E9: 41551330 | F9: Mariana Rubio | G9: 5552172835 | H9: mariana.rubio@oriflame.com | K9: Multinivel belleza, volumen alto constante
A10: =IF(E10>=20000000,"1 - Alta",IF(E10>=5000000,"2 - Media","3 - Baja")) -> 1 - Alta | B10: FARMASI | C10: CDMX (multinivel) | D10: Belleza - venta directa | E10: 34929674 | F10: Eduardo Aguilar | G10: 5514512332 | H10: eduardo.aguilar@farmasi.com | K10: Multinivel belleza en crecimiento en MX
A11: =IF(E11>=20000000,"1 - Alta",IF(E11>=5000000,"2 - Media","3 - Baja")) -> 1 - Alta | B11: OFFICE DEPOT DE MEXICO | C11: CDMX Norte | D11: Papelería/oficina omnicanal | E11: 33790064 | F11: LUZ MARIA LARIO | G11: 5531497036 | H11: llarios@officedepot.com.mx | K11: Ecommerce fuerte, paquete ligero, CDMX
A12: =IF(E12>=20000000,"1 - Alta",IF(E12>=5000000,"2 - Media","3 - Baja")) -> 1 - Alta | B12: NESPRESSO MEXICO | C12: CDMX Sur | D12: Café D2C | E12: 30614105 | F12: Yessica Pazarán | G12: 55 8040 2463 | H12: yessicaIsabel.Pazaran@nespresso.com | I12: Ana Laura García Linares | J12: ana.garcia1@nespresso.com | K12: Suscripciones recurrentes, paquete ligero, CDMX
A13: =IF(E13>=20000000,"1 - Alta",IF(E13>=5000000,"2 - Media","3 - Baja")) -> 1 - Alta | B13: WALDO'S DOLAR MART DE MEXICO | C13: CDMX (departamentales) / CDMX Sur | D13: Retail descuento | E13: 28910598 | F13: DIANA HAIDE HERNANDEZ | H13: reyesdh@Waldos.com | K13: Canal ecommerce en expansión (TikTok Shop +159% MoM)
A14: =IF(E14>=20000000,"1 - Alta",IF(E14>=5000000,"2 - Media","3 - Baja")) -> 1 - Alta | B14: PRIVALIA VENTA DIRECTA | C14: CDMX (e-commerce) | D14: Moda - eCommerce outlet | E14: 26993752 | F14: KAREN LUNA | G14: 5566884841 | H14: kluna@grupoaxo.com | K14: Flash sales = picos de volumen, CDMX (Grupo Axo)
A15: =IF(E15>=20000000,"1 - Alta",IF(E15>=5000000,"2 - Media","3 - Baja")) -> 1 - Alta | B15: DITERMAX CORPORATE | C15: Puebla | D15: Calzado | E15: 25947690 | F15: Ing. Pedro Vazquez Aragón | G15: 2225050008 | H15: pedrov@pakar.com | I15: Ing. Pedro Vazquez Aragón | J15: pedrov@pakar.com | K15: Pakar PUE, distribuye calzado a comercios
A16: =IF(E16>=20000000,"1 - Alta",IF(E16>=5000000,"2 - Media","3 - Baja")) -> 1 - Alta | B16: MARY KAY COSMETICS DE MEXICO | C16: Monterrey | D16: Belleza - venta directa | E16: 25597813 | F16: Adrian Rodriguez | G16: 8180186761 | H16: Adrian.RodriguezValdez@mkcorp.com | K16: Multinivel belleza, CEDIS MTY
A17: =IF(E17>=20000000,"1 - Alta",IF(E17>=5000000,"2 - Media","3 - Baja")) -> 1 - Alta | B17: NIKKEN LATINOAMERICA | C17: CDMX (multinivel) | D17: Bienestar - venta directa | E17: 23307565 | F17: victor garcia | G17: 556097545 | H17: victor.garcia@nikkelatam.com | K17: Multinivel bienestar | L17: Celular no tiene 10 dígitos
A18: =IF(E18>=20000000,"1 - Alta",IF(E18>=5000000,"2 - Media","3 - Baja")) -> 1 - Alta | B18: SERVICIOS SHASA | C18: CDMX (departamentales) | D18: Moda fast-fashion | E18: 21580454 | F18: Diana Laura German Ramirez | G18: 5548700729 | H18: dgermanr@shasa.com | K18: Shasa, ecommerce + tiendas, CDMX
A19: =IF(E19>=20000000,"1 - Alta",IF(E19>=5000000,"2 - Media","3 - Baja")) -> 1 - Alta | B19: OMNILIFE DE MEXICO | C19: Guadalajara | D19: Suplementos - venta directa | E19: 20319562 | F19: Shira León | G19: 3313275397 | H19: shira.leon@omnilife.com | K19: Multinivel suplementos, CEDIS GDL
A20: =IF(E20>=20000000,"1 - Alta",IF(E20>=5000000,"2 - Media","3 - Baja")) -> 2 - Media | B20: CLOE MODA | C20: Guadalajara | D20: Moda/bolsos D2C | E20: 19923867 | F20: Jesús Aurelio Ugalde Barajas | G20: 3318921733 | H20: jesusb@oemoda.com | K20: Marca mexicana de bolsas, ecommerce propio, GDL
A21: =IF(E21>=20000000,"1 - Alta",IF(E21>=5000000,"2 - Media","3 - Baja")) -> 2 - Media | B21: ENCANTO MEXICO | C21: CDMX (e-commerce) | D21: Moda/calzado | E21: 18955360 | F21: ALFONZO LOPEZ | G21: 5534557823 | H21: alfonzo.lopez@encanto.com.mx | K21: Distribuidor marcas, CDMX ecommerce
A22: =IF(E22>=20000000,"1 - Alta",IF(E22>=5000000,"2 - Media","3 - Baja")) -> 2 - Media | B22: LUIS HIRAM HUERTA REYES | C22: Occidente/GDL (confirmar) | D22: Seller marketplace (persona física) | E22: 18942815 | F22: Luis Hiram Huerta | H22: Revendedor | K22: Persona física con alto gasto en paquetería: probable seller Mercado Libre/Amazon. Validar giro | L22: Correo con formato inválido
A23: =IF(E23>=20000000,"1 - Alta",IF(E23>=5000000,"2 - Media","3 - Baja")) -> 2 - Media | B23: NU SKIN MEXICO | C23: CDMX (multinivel) | D23: Belleza - venta directa | E23: 18852726 | F23: Alicia Sanchez | G23: 5541303204 | H23: asanchezc@nuskin.com | K23: Multinivel belleza
A24: =IF(E24>=20000000,"1 - Alta",IF(E24>=5000000,"2 - Media","3 - Baja")) -> 2 - Media | B24: ODESA | C24: CDMX Sur | D24: Óptica/retail | E24: 16982012 | F24: Alan Santiago Garcia Cruz | G24: 5579468259 | H24: asgarcia@devlyn.com.mx | I24: Maribel Hernandez Suarez | J24: hmaribel@devlyn.com.mx | K24: Devlyn: paquete pequeño, CDMX
A25: =IF(E25>=20000000,"1 - Alta",IF(E25>=5000000,"2 - Media","3 - Baja")) -> 2 - Media | B25: HUAWEI TECHNOLOGIES DE MEXICO | C25: CDMX Sur | D25: Electrónica pequeña | E25: 16754304 | F25: Francisco Casanova Haro | G25: 5548841894 | H25: francisco.casanova.haro@huawei.com | I25: Miguel Angel Urquiza | J25: miguel.urquiza@huawei.com | K25: Ecommerce CDMX
A26: =IF(E26>=20000000,"1 - Alta",IF(E26>=5000000,"2 - Media","3 - Baja")) -> 2 - Media | B26: MASCOTAS Y COMPAÑIA | C26: CDMX Norte | D26: Pet retail omnicanal | E26: 16126682 | F26: Juan Carlos Uribe | G26: 5519194537 | H26: jcuribe@petco.com.mx | K26: Petco México, paquete ligero-mediano, CDMX
A27: =IF(E27>=20000000,"1 - Alta",IF(E27>=5000000,"2 - Media","3 - Baja")) -> 2 - Media | B27: DISTRIBUIDOR CELULAR DE LA ZONA | C27: CDMX Norte / CDMX Sur | D27: Accesorios celular | E27: 15719364 | F27: Cuauhtémoc Orozco | G27: 5559513870 | H27: corozco@mobo.mx | I27: Cuauhtémoc Orozco | J27: corozco@mobo.mx | K27: MOBO: accesorios ligeros, alto volumen, CDMX
A28: =IF(E28>=20000000,"1 - Alta",IF(E28>=5000000,"2 - Media","3 - Baja")) -> 2 - Media | B28: HY CITE MEXICO | C28: Guadalajara | D28: Hogar - venta directa | E28: 15366901 | F28: RAYNALDO LEON | G28: 3312524444 | H28: rleon1@hycite.com | K28: Royal Prestige, GDL
A29: =IF(E29>=20000000,"1 - Alta",IF(E29>=5000000,"2 - Media","3 - Baja")) -> 2 - Media | B29: TERRAMAR BRANDS | C29: Guadalajara | D29: Belleza - venta directa | E29: 15062414 | F29: Alberto Ceballos | G29: 3335526354 | H29: aceballos@terramarbrans.com | K29: Cosméticos GDL, multinivel
A30: =IF(E30>=20000000,"1 - Alta",IF(E30>=5000000,"2 - Media","3 - Baja")) -> 2 - Media | B30: AUTO-TODO MEXICANA | C30: Puebla | D30: Refacciones auto | E30: 14637547 | F30: Roberto Alonso Gordon | G30: 2227946970 | H30: roberto_alonso@autotodo.com | I30: Guadalupe Lizet Leyva Moreno | J30: guadalupe_leyva@autotodo.com | K30: Distribuidor PUE, envíos frecuentes a talleres
A31: =IF(E31>=20000000,"1 - Alta",IF(E31>=5000000,"2 - Media","3 - Baja")) -> 2 - Media | B31: XK MEDIA | C31: Monterrey | D31: Retail/marketplace | E31: 14415253 | F31: Jorge Villanueva | G31: 8126667319 | H31: jvillanuevan@falabella.com.mx | K31: Linio-Falabella legacy - validar operación actual | L31: Correo no corresponde al dominio de la empresa (falabella)
A32: =IF(E32>=20000000,"1 - Alta",IF(E32>=5000000,"2 - Media","3 - Baja")) -> 2 - Media | B32: XIAOMI SOFTWARE DE MEXICO | C32: CDMX Sur | D32: Electrónica pequeña | E32: 13980873 | F32: Dennis Duan 段勇 | G32: +86 135 2889 7629 | H32: duanyong1@xiaomi.com | I32: Ernesto Abraham Enriquez Villegas | J32: ernestoabraham@xiaomi.com | K32: Ecommerce mi.com + marketplaces, CDMX
A33: =IF(E33>=20000000,"1 - Alta",IF(E33>=5000000,"2 - Media","3 - Baja")) -> 2 - Media | B33: DISTRIBUCIONES SAGAJI | C33: Puebla | D33: Consumo masivo | E33: 13867156 | F33: Ing Julio Javier Vergara Silva | G33: 5513846480 | H33: julio.vergara@sagaji.com.mx | I33: Ing Julio Javier Vergara Silva | J33: julio.vergara@sagaji.com.mx | K33: Distribuidor PUE
A34: =IF(E34>=20000000,"1 - Alta",IF(E34>=5000000,"2 - Media","3 - Baja")) -> 2 - Media | B34: MOTOCICLETAS Y EQUIPOS | C34: Monterrey | D34: Refacciones moto | E34: 13363695 | F34: Luis Navarro | G34: 3334566072 | H34: luis.navarro@tvc.mx | K34: Motos y Equipos MTY, distribuye a comercios | L34: Correo parece de otra empresa (tvc.mx)
A35: =IF(E35>=20000000,"1 - Alta",IF(E35>=5000000,"2 - Media","3 - Baja")) -> 2 - Media | B35: EDITORIAL PANINI MEXICO | C35: CDMX Norte | D35: Editorial/coleccionables | E35: 13200146 | F35: Aldo Covarrubias | G35: 5527143533 | H35: jlogistica@panini.com.mx | I35: Aldo Covarrubias | J35: jlogistica@panini.com.mx | K35: Paquete ligero, CDMX
A36: =IF(E36>=20000000,"1 - Alta",IF(E36>=5000000,"2 - Media","3 - Baja")) -> 2 - Media | B36: TVCENLINEA.COM | C36: Monterrey | D36: Tecnología/seguridad B2B | E36: 12627725 | F36: Carmen Guajardo Suro | H36: cguajardo@fossil.com | K36: TVC MTY: distribuidor con envíos diarios a integradores | L36: Correo no corresponde al dominio de la empresa (fossil.com)
A37: =IF(E37>=20000000,"1 - Alta",IF(E37>=5000000,"2 - Media","3 - Baja")) -> 2 - Media | B37: YVES ROCHER DE MEXICO | C37: CDMX (multinivel) | D37: Belleza - venta directa | E37: 12197451 | F37: Carolina Cruz | G37: 5521095980 | H37: carolina.cruz@yrnet.com | K37: Multinivel belleza
A38: =IF(E38>=20000000,"1 - Alta",IF(E38>=5000000,"2 - Media","3 - Baja")) -> 2 - Media | B38: MASLUZ.MX | C38: Puebla | D38: Iluminación eCommerce | E38: 11703720 | F38: Juan Pablo Dominguez | G38: 2222609754 | H38: juanpablo@gme.mx | I38: Pablo Basilio | J38: gerente.logistica@gme.mx | K38: Ecommerce de iluminación, PUE
A39: =IF(E39>=20000000,"1 - Alta",IF(E39>=5000000,"2 - Media","3 - Baja")) -> 2 - Media | B39: GRUPO ELECZION, | C39: CDMX (departamentales) | D39: Retail descuento | E39: 11562694 | F39: DIANA HAIDE HERNANDEZ | H39: reyesdh@Waldos.com | K39: Hermana de Waldo's | L39: Correo no corresponde al dominio de la empresa (Waldos.com)
A40: =IF(E40>=20000000,"1 - Alta",IF(E40>=5000000,"2 - Media","3 - Baja")) -> 2 - Media | B40: PUNDEN | C40: Guadalajara | D40: eCommerce | E40: 11386654 | F40: FABIOLA FONG | G40: 3344563233 | H40: admon.punden@gmail.com | K40: GDL, validar giro | L40: Correo personal, no corporativo
...

Sheet Canal - Alianzas
A1: Prioridad | B1: Razón social | C1: Ciudad de recolección | D1: Industria / giro | E1: Ingreso anual con Estafeta (MXN) | F1: Contacto 1 | G1: Celular | H1: Correo | I1: Contacto 2 | J1: Correo 2 | K1: Nota de fit iMile | L1: Errores / datos a corregir
A2: Alianza | B2: TENDENCYS INNOVATIONS | C2: Monterrey | D2: Logística/plataforma | E2: 1.8215019e+08 | F2: Gabriel Garza | G2: 8118414502 | H2: gabriel.garza@tendencys.com | K2: Agregador, 3PL o plataforma: posible alianza de capacidad, no cliente directo
A3: Alianza | B3: PAKKE MEXICO | C3: CDMX Norte | D3: Logística/plataforma | E3: 54455070 | F3: ERIK TORRES | G3: 5523104558 | H3: erik.torres@pakke.com | I3: JOSEP ROMAGOSA | J3: josep.romagosa@pakke.com | K3: Agregador, 3PL o plataforma: posible alianza de capacidad, no cliente directo
A4: Alianza | B4: ENVIOCLICK | C4: CDMX Sur | D4: Logística/plataforma | E4: 38194943 | F4: Rosa Costes | G4: 5564131570 | H4: rosa@envioclick.com | I4: Rosa Costes | J4: rosa@envioclick.com | K4: Agregador, 3PL o plataforma: posible alianza de capacidad, no cliente directo
A5: Alianza | B5: PROMOLOGISTICS | C5: CDMX Norte | D5: Logística/plataforma | E5: 37523417 | F5: FELIPE ORDOÑEZ | G5: 5511050773 | H5: fordonez@promologistics.com.mx | I5: Jonatan Olmos | J5: jolmos@promologistics.com.mx | K5: Agregador, 3PL o plataforma: posible alianza de capacidad, no cliente directo
A6: Alianza | B6: INOVIT | C6: Monterrey | D6: Logística/plataforma | E6: 33918521 | F6: Pablo Salinas | G6: 8112901501 | H6: pablo@enviatodo.com | K6: Agregador, 3PL o plataforma: posible alianza de capacidad, no cliente directo
A7: Alianza | B7: SHIPPER EXPRESS | C7: Puebla | D7: Logística/plataforma | E7: 28969806 | F7: Marco Serrato | G7: 2212141945 | H7: marco.s@myshipper.com.mx | I7: Marco Serrato | J7: marco.s@myshipper.com.mx | K7: Agregador, 3PL o plataforma: posible alianza de capacidad, no cliente directo
A8: Alianza | B8: GETCUBBO | C8: Guadalajara | D8: Logística/plataforma | E8: 27552662 | F8: Agustin Ortiz Monasterio | G8: 5542183500 | H8: agustin@cubbo.com | K8: Agregador, 3PL o plataforma: posible alianza de capacidad, no cliente directo
A9: Alianza | B9: GRUPO PGL MEXICO | C9: Monterrey | D9: Logística/plataforma | E9: 24526462 | F9: Maribel Esquivel | G9: 8117381238 | H9: maribel.esquivel@pak2go.com | K9: Agregador, 3PL o plataforma: posible alianza de capacidad, no cliente directo
A10: Alianza | B10: SEGMAIL | C10: CDMX Sur | D10: Logística/plataforma | E10: 23142844 | F10: Gabriel Olmedo | G10: 5530076181 | H10: golmedo@segmail.co | I10: Jonathan Esses | J10: jonathan@segmail.co | K10: Agregador, 3PL o plataforma: posible alianza de capacidad, no cliente directo | L10: Correo personal, no corporativo
A11: Alianza | B11: ECOMSUR MX | C11: CDMX Norte | D11: Logística/plataforma | E11: 18840064 | F11: Pedro Albo Fernandez | G11: 5518080471 | H11: pealbo@infracommerce.lat | I11: Pedro Albo Fernandez | J11: pealbo@infracommerce.lat | K11: Agregador, 3PL o plataforma: posible alianza de capacidad, no cliente directo
A12: Alianza | B12: MELLON TECHNOLOGY 4 LOGISTICS | C12: Puebla | D12: Logística/plataforma | E12: 13535857 | F12: Eduardo Higuera | G12: 5552131073 | H12: eduardo@mellont4l.com | I12: Eduardo Higuera | J12: eduardo@mellont4l.com | K12: Agregador, 3PL o plataforma: posible alianza de capacidad, no cliente directo
A13: Alianza | B13: CEDIS ALCE | C13: CDMX (CDL) | D13: Logística/plataforma | E13: 12535224 | F13: ROBERTO BERMEO | G13: 7223049242 | H13: carlos.bermeo@vertiche.com.mx | I13: ROBERTO BERMEO | J13: carlos.bermeo@vertiche.com.mx | K13: Agregador, 3PL o plataforma: posible alianza de capacidad, no cliente directo
A14: Alianza | B14: ZIIPCO LOGISTIC | C14: CDMX (CDL) | D14: Logística/plataforma | E14: 11642271 | F14: DANIEL CUBILLAS | G14: 3332407906 | H14: daniel.cubillas@ziipco.com.mx | I14: DANIEL CUBILLAS | J14: daniel.cubillas@ziipco.com.mx | K14: Agregador, 3PL o plataforma: posible alianza de capacidad, no cliente directo
A15: Alianza | B15: LOGISFASHION MEXICO | C15: CDMX Norte | D15: Logística/plataforma | E15: 11301995 | F15: Luis Giovanny Ascencio Ruiz | G15: 5530336935 | H15: lgascencio.mex@logisfashion.com | I15: Edwin Hernan Leon Tirado | J15: ehleon.mex@logisfashion.com | K15: Agregador, 3PL o plataforma: posible alianza de capacidad, no cliente directo
A16: Alianza | B16: BAZAYA MEXICO | C16: CDMX (e-commerce) | D16: Logística/plataforma | E16: 4526368.8 | F16: cliete cerro operaciones en México el 2024 | K16: Agregador, 3PL o plataforma: posible alianza de capacidad, no cliente directo | L16: Contacto inválido (ya no trabaja / cerró); Sin correo
A17: Alianza | B17: KEKKA SOLUCIONES EN ECOMMERCE | C17: Occidente/GDL (confirmar) | D17: Logística/plataforma | E17: 4133077 | F17: Verónica Adriana Juarez Jimenez | G17: 3327530775 | H17: gerenciaeasyecommerce@gmail.com | I17: Verónica Adriana Juarez Jimenez | J17: gerenciaeasyecommerce@gmail.com | K17: Agregador, 3PL o plataforma: posible alianza de capacidad, no cliente directo | L17: Correo personal, no corporativo
A18: Alianza | B18: 6 Y 7 TECNOLOGIAS INTEGRALES | C18: Puebla | D18: Logística/plataforma | E18: 3900373.4 | F18: Eduardo Higuera | G18: 5552131073 | H18: eduardo@mellont4l.com | I18: Eduardo Higuera | J18: eduardo@mellont4l.com | K18: Agregador, 3PL o plataforma: posible alianza de capacidad, no cliente directo
A19: Alianza | B19: MKOMM LOGISTICS | C19: Occidente/GDL (confirmar) | D19: Logística/plataforma | E19: 2922323.7 | F19: Manuel Carreon | G19: 3311216033 | H19: mkommlogistics@gmail.com | K19: Agregador, 3PL o plataforma: posible alianza de capacidad, no cliente directo
A20: Alianza | B20: ENVIOPACK MEXICO | C20: CDMX (e-commerce) | D20: Logística/plataforma | E20: 1993822.4 | F20: MARLENE AGUILAR RODRIGUEZ | G20: 5539024301 | H20: marlene@enviopack.com | I20: Horacio Esteves | J20: horacio@enviopack.com | K20: Agregador, 3PL o plataforma: posible alianza de capacidad, no cliente directo
A21: Alianza | B21: GENKA LOGISTICS | C21: Occidente/GDL (confirmar) | D21: Logística/plataforma | E21: 1805942.1 | F21: Raquel Velazquez | H21: rvelazquez@genka.mx | K21: Agregador, 3PL o plataforma: posible alianza de capacidad, no cliente directo
A22: Alianza | B22: LOGISCTASH | C22: CDMX (CDL) | D22: Logística/plataforma | E22: 1578780.3 | F22: AUREA SANCHEZ | G22: 5516940015 | H22: direccioncomercial@tssconsultores.com | K22: Agregador, 3PL o plataforma: posible alianza de capacidad, no cliente directo
A23: Alianza | B23: TREBOR LOGISTICS | C23: CDMX (CDL) | D23: Logística/plataforma | E23: 1366351 | F23: PORFIRIO SANCHEZ MERINO | G23: 7774843183 | H23: p.sanchez.trebor@gmail.com | I23: PORFIRIO SANCHEZ MERINO | J23: p.sanchez.trebor@gmail.com | K23: Agregador, 3PL o plataforma: posible alianza de capacidad, no cliente directo
A24: Alianza | B24: EDARKSTORE | C24: CDMX (CDL) | D24: Logística/plataforma | E24: 1204432.4 | F24: CRISTIAN AUSTIN | H24: causin@edarkstore.cl | I24: CRISTIAN AUSTIN | J24: causin@edarkstore.cl | K24: Agregador, 3PL o plataforma: posible alianza de capacidad, no cliente directo
A25: Alianza | B25: BLUE COMMERCE ENTERPRISES | C25: CDMX (CDL) | D25: Logística/plataforma | E25: 882907.66 | F25: MARCOS RABADAN DIEGO | G25: 7771395869 | H25: auxiliarcontabilidad@imtra.com.mx | I25: MARCOS RABADAN DIEGO | J25: auxiliarcontabilidad@imtra.com.mx | K25: Agregador, 3PL o plataforma: posible alianza de capacidad, no cliente directo
A26: Alianza | B26: LIDERANDO MARKETPLACE | C26: CDMX (e-commerce) | D26: Logística/plataforma | E26: 135165.75 | F26: PAULINA GONZALEZ | G26: 5531923276 | H26: pgonzalez@gaon.mx | K26: Agregador, 3PL o plataforma: posible alianza de capacidad, no cliente directo
A27: Alianza | B27: DISBYTE DE MEXICO | C27: CDMX (e-commerce) | D27: Logística/plataforma | E27: 32606.85 | F27: DI LULLO LEONARDO | G27: 1124014254 | H27: ldilullo@disbyte.com | K27: Agregador, 3PL o plataforma: posible alianza de capacidad, no cliente directo

Sheet Excluidas
A1: Razón social | B1: Ciudad | C1: Ingreso (MXN) | D1: Motivo de exclusión
A2: SERVICIOS COMERCIALES AMAZON MEXICO | B2: CDMX (e-commerce) | C2: 7.9212276e+08 | D2: Gran cuenta con logística consolidada o flotilla propia; solo entrar con señal de churn
A3: DISTRIBUIDORA LIVERPOOL | B3: CDMX (departamentales) / CDMX Sur | C3: 7.8607138e+08 | D3: Gran cuenta con logística consolidada o flotilla propia; solo entrar con señal de churn
A4: NU MEXICO FINANCIERA | B4: CDMX Sur | C4: 3.7044693e+08 | D4: Giro financiero/industrial/documentos o B2B pesado; no fit de paquete <30kg B2C
A5: SUBURBIA S DE RL DE CV | B5: CDMX (departamentales) / CDMX Sur | C5: 1.191577e+08 | D5: Gran cuenta con logística consolidada o flotilla propia; solo entrar con señal de churn
A6: H & M HENNES & MAURITZ | B6: CDMX Norte | C6: 1.1202927e+08 | D6: Gran cuenta con logística consolidada o flotilla propia; solo entrar con señal de churn
A7: COSTCO DE MEXICO | B7: CDMX Norte | C7: 99480822 | D7: Gran cuenta con logística consolidada o flotilla propia; solo entrar con señal de churn
A8: NUEVA WAL MART DE MEXICO | B8: CDMX (e-commerce) | C8: 86818039 | D8: Gran cuenta con logística consolidada o flotilla propia; solo entrar con señal de churn
A9: ZARA MEXICO CONTRATO 1 | B9: CDMX (e-commerce) | C9: 84603778 | D9: Gran cuenta con logística consolidada o flotilla propia; solo entrar con señal de churn
A10: ULINE SHIPPING SUPPLIES | B10: Monterrey | C10: 80236392 | D10: Gran cuenta con logística consolidada o flotilla propia; solo entrar con señal de churn
A11: DEREMATE.COM DE MEXICO | B11: CDMX (e-commerce) | C11: 71023470 | D11: Gran cuenta con logística consolidada o flotilla propia; solo entrar con señal de churn
A12: ITX RETAIL MEXICO | B12: CDMX (e-commerce) | C12: 56819526 | D12: Gran cuenta con logística consolidada o flotilla propia; solo entrar con señal de churn
A13: ALVACO ENTERPRISES | B13: CDMX Sur | C13: 46340050 | D13: Giro financiero/industrial/documentos o B2B pesado; no fit de paquete <30kg B2C
... A120: AMERICAN COTTON | B120: CDMX (CDL) | C120: 200 | D120: Giro financiero/industrial/documentos o B2B pesado; no fit de paquete <30kg B2C

Sheet Resumen
A1: Resumen de calificación vs ICP iMile
A3: Prospectos calificados (A/B) | B3: =COUNTA('Prospectos iMile'!B2:B83) -> 82
A4: → Prioridad Alta (≥$20M ingreso Estafeta) | B4: =COUNTIF('Prospectos iMile'!A2:A83,"1 - Alta") -> 18
A5: → Prioridad Media ($5-20M) | B5: =COUNTIF('Prospectos iMile'!A2:A83,"2 - Media") -> 42
A6: → Prioridad Baja (<$5M) | B6: =COUNTIF('Prospectos iMile'!A2:A83,"3 - Baja") -> 22
A7: Canal / alianzas (3PL, agregadores, plataformas) | B7: =COUNTA('Canal - Alianzas'!B2:B27) -> 26
A8: Excluidas (saturadas, flotilla propia o fuera de ICP) | B8: =COUNTA(Excluidas!A2:A120) -> 119
A9: Con errores de datos a corregir | B9: =COUNTIF('Prospectos iMile'!L2:L83,"?*") -> 14
A11: Criterios: recolección en CDMX/EdoMex, GDL, MTY o PUE; paquete <30kg; B2C/D2C/marketplace o distribución frecuente a comercios. Ingreso = gasto anual con Estafeta (proxy de volumen).
